<?xml version="1.0"?>
<robot xmlns:xacro="http://www.ros.org/wiki/xacro" name="3bodies">

   <!-- Example link -->
    <link name="world">
    </link>

    <joint name="world2odom_joint" type="continuous">
        <parent link="world"/>
        <child link="odom"/>
        <origin xyz="0.5 0.5 0.5"/>    
        <axis xyz="1 0 0"/>
    </joint>

    <!-- Example link -->
    <link name="odom">
    </link>
 

    <joint name="odom2base_joint" type="continuous">
        <parent link="odom"/>
        <child link="base_link"/>
        <origin xyz="0.5 0 0"/>  
        <axis xyz="0 1 0"/>  
    </joint>

   
    <!-- Example link -->
    <link name="base_link">
    </link>

        <joint name="joint3" type="continuous">
        <parent link="base_link"/>
        <child link="body3"/>
        <origin xyz="0.5 0 0"/>  
        <axis xyz="0 0 1"/>  
    </joint>

   
    <!-- Example link -->
    <link name="body3">
    </link>

</robot>